Workbook

Sheet Raw_data
A1: company | B1: ticker | C1: fiscal_year | D1: revenue | E1: net_income | F1: total_assets | G1: total_liabilities | H1: revenue_growth_pct | I1: net_profit_margin_pct | J1: roa_pct | K1: liability_to_asset_pct
A2: Adobe | B2: ADBE | C2: 2021 | D2: 15.785 | E2: 4.822 | F2: 27.241 | G2: 12.444 | I2: 30.54798859676908 | J2: 17.70125913145626 | K2: 45.68114239565361
A3: Adobe | B3: ADBE | C3: 2022 | D3: 17.606 | E3: 4.756 | F3: 27.165 | G3: 13.114 | H3: 11.536268609439349 | I3: 27.013518118823125 | J3: 17.507822565801582 | K3: 48.275354316215726
A4: Adobe | B4: ADBE | C4: 2023 | D4: 19.409 | E4: 5.428 | F4: 29.779 | G4: 13.261 | H4: 10.24082699079858 | I4: 27.96640733680252 | J4: 18.22761006078109 | K4: 44.531381174653276
A5: Adobe | B5: ADBE | C5: 2024 | D5: 21.505 | E5: 5.56 | F5: 30.23 | G5: 16.125 | H5: 10.799113813179462 | I5: 25.854452452917926 | J5: 18.392325504465763 | K5: 53.34105193516374
A6: Adobe | B6: ADBE | C6: 2025 | D6: 23.769 | E6: 7.13 | F6: 29.496 | G6: 17.873 | H6: 10.527784236224136 | I6: 29.99705498758888 | J6: 24.172769189042583 | K6: 60.594656902630874
A7: Alphabet | B7: GOOGL | C7: 2021 | D7: 257.637 | E7: 76.033 | F7: 359.268 | G7: 107.633 | I7: 29.511677282377917 | J7: 21.163309841121393 | K7: 29.958972132224414
A8: Alphabet | B8: GOOGL | C8: 2022 | D8: 282.836 | E8: 59.972 | F8: 365.264 | G8: 109.12 | H8: 9.78081564371578 | I8: 21.203807153261963 | J8: 16.418809409084936 | K8: 29.874282710587412
A9: Alphabet | B9: GOOGL | C9: 2023 | D9: 307.394 | E9: 73.795 | F9: 402.392 | G9: 119.013 | H9: 8.68277022726951 | I9: 24.006649446638516 | J9: 18.33908228791825 | K9: 29.5763832282948
A10: Alphabet | B10: GOOGL | C10: 2024 | D10: 350.018 | E10: 100.118 | F10: 450.256 | G10: 125.172 | H10: 13.86624332290154 | I10: 28.603671811164 | J10: 22.235794747876763 | K10: 27.800184783767456
A11: Alphabet | B11: GOOGL | C11: 2025 | D11: 402.836 | E11: 132.17 | F11: 595.281 | G11: 180.016 | H11: 15.090081081544394 | I11: 32.80987796522654 | J11: 22.202959610671265 | K11: 30.24050826416432
A12: Amazon | B12: AMZN | C12: 2021 | D12: 469.822 | E12: 33.364 | F12: 420.549 | G12: 282.304 | I12: 7.101412875514555 | J12: 7.933439385184604 | K12: 67.127492872412
A13: Amazon | B13: AMZN | C13: 2022 | D13: 513.983 | E13: -2.722 | F13: 462.675 | G13: 316.632 | H13: 9.399517263985068 | I13: -0.5295895 | J13: -0.58831793 | K13: 68.43507861890096
A14: Amazon | B14: AMZN | C14: 2023 | D14: 574.785 | E14: 30.425 | F14: 527.854 | G14: 325.979 | H14: 11.82957412988368 | I14: 5.293283575597832 | J14: 5.763904412962675 | K14: 61.75552330758125
A15: Amazon | B15: AMZN | C15: 2024 | D15: 637.959 | E15: 59.248 | F15: 624.894 | G15: 338.924 | H15: 10.990892246666139 | I15: 9.287117197186653 | J15: 9.481288026449285 | K15: 54.23703860174685
A16: Amazon | B16: AMZN | C16: 2025 | D16: 716.924 | E16: 77.67 | F16: 818.042 | G16: 406.977 | H16: 12.377754683294695 | I16: 10.83378433418326 | J16: 9.494622525493801 | K16: 49.75013507863899
A17: Apple | B17: AAPL | C17: 2021 | D17: 365.817 | E17: 94.68 | F17: 351.002 | G17: 287.912 | I17: 25.881793355694242 | J17: 26.974205275183614 | K17: 82.0257434430573
A18: Apple | B18: AAPL | C18: 2022 | D18: 394.328 | E18: 99.803 | F18: 352.755 | G18: 302.083 | H18: 7.793787604184588 | I18: 25.309640705199733 | J18: 28.292440929256852 | K18: 85.6353559836147
A19: Apple | B19: AAPL | C19: 2023 | D19: 383.285 | E19: 96.995 | F19: 352.583 | G19: 290.437 | H19: -2.8004605 | I19: 25.30623426432028 | J19: 27.50983456377647 | K19: 82.37407929480433
A20: Apple | B20: AAPL | C20: 2024 | D20: 391.035 | E20: 93.736 | F20: 364.98 | G20: 308.03 | H20: 2.021994077514111 | I20: 23.971255769943866 | J20: 25.682503150857585 | K20: 84.39640528248123
A21: Apple | B21: AAPL | C21: 2025 | D21: 416.161 | E21: 112.01 | F21: 359.241 | G21: 285.508 | H21: 6.425511782832727 | I21: 26.91506412181824 | J21: 31.17962593356549 | K21: 79.47533828265705
A22: Cisco | B22: CSCO | C22: 2021 | D22: 49.818 | E22: 10.591 | F22: 97.497 | G22: 56.222 | I22: 21.259384158336346 | J22: 10.86289834559012 | K22: 57.665364062483974
A23: Cisco | B23: CSCO | C23: 2022 | D23: 51.557 | E23: 11.812 | F23: 94.002 | G23: 54.229 | H23: 3.490706170460478 | I23: 22.91056500572182 | J23: 12.565690091700176 | K23: 57.689198102168035
A24: Cisco | B24: CSCO | C24: 2023 | D24: 56.998 | E24: 12.613 | F24: 101.852 | G24: 57.499 | H24: 10.553368116841554 | I24: 22.12884662619741 | J24: 12.38365471468405 | K24: 56.45348152220869
A25: Cisco | B25: CSCO | C25: 2024 | D25: 53.803 | E25: 10.32 | F25: 124.413 | G25: 78.956 | H25: -5.6054598 | I25: 19.18108655651172 | J25: 8.294953099756457 | K25: 63.462821409338254
A26: Cisco | B26: CSCO | C26: 2025 | D26: 56.654 | E26: 10.18 | F26: 122.291 | G26: 75.448 | H26: 5.298961024478199 | I26: 17.968722420305713 | J26: 8.324406538502425 | K26: 61.69546409793034
A27: IBM | B27: IBM | C27: 2021 | D27: 57.35 | E27: 5.743 | F27: 132.001 | G27: 113.005 | I27: 10.013949433304273 | J27: 4.3507246157226085 | K27: 85.60919993030355
A28: IBM | B28: IBM | C28: 2022 | D28: 60.53 | E28: 1.639 | F28: 127.243 | G28: 105.222 | H28: 5.544899738448117 | I28: 2.7077482240211466 | J28: 1.2880865745070458 | K28: 82.69374346722412
A29: IBM | B29: IBM | C29: 2023 | D29: 61.86 | E29: 7.502 | F29: 135.241 | G29: 112.628 | H29: 2.197257558235588 | I29: 12.127384416424183 | J29: 5.547134374930678 | K29: 83.279478856264
A30: IBM | B30: IBM | C30: 2024 | D30: 62.753 | E30: 6.023 | F30: 137.175 | G30: 109.783 | H30: 1.4435822825735523 | I30: 9.59794750848565 | J30: 4.390741753234918 | K30: 80.03134681975578
A31: IBM | B31: IBM | C31: 2025 | D31: 67.535 | E31: 10.593 | F31: 151.88 | G31: 119.139 | H31: 7.6203528118177655 | I31: 15.685200266528469 | J31: 6.974585198841191 | K31: 78.44284961811957
A32: Meta | B32: META | C32: 2021 | D32: 117.929 | E32: 39.37 | F32: 165.987 | G32: 41.108 | I32: 33.38449405998524 | J32: 23.718724960388464 | K32: 24.765794911649706
A33: Meta | B33: META | C33: 2022 | D33: 116.609 | E33: 23.2 | F33: 185.727 | G33: 60.014 | H33: -1.1193176 | I33: 19.895548371051976 | J33: 12.491452508251358 | K33: 32.31301857026712
A34: Meta | B34: META | C34: 2023 | D34: 134.902 | E34: 39.098 | F34: 229.623 | G34: 76.455 | H34: 15.687468377226455 | I34: 28.982520644616095 | J34: 17.02703997421861 | K34: 33.29588063913459
A35: Meta | B35: META | C35: 2024 | D35: 164.501 | E35: 62.36 | F35: 276.054 | G35: 93.417 | H35: 21.941112807816054 | I35: 37.90858414234564 | J35: 22.589783158367567 | K35: 33.8401182377361
A36: Meta | B36: META | C36: 2025 | D36: 200.966 | E36: 60.458 | F36: 366.021 | G36: 148.778 | H36: 22.167038498246217 | I36: 30.08369574952977 | J36: 16.517631502017643 | K36: 40.64739454840022
A37: Microsoft | B37: MSFT | C37: 2021 | D37: 168.088 | E37: 61.271 | F37: 333.779 | G37: 191.791 | I37: 36.45173956498977 | J37: 18.356757015869782 | K37: 57.46047534446445
A38: Microsoft | B38: MSFT | C38: 2022 | D38: 198.27 | E38: 72.738 | F38: 364.84 | G38: 198.298 | H38: 17.956070629670172 | I38: 36.68633681343622 | J38: 19.936958666812853 | K38: 54.35204473193729
A39: Microsoft | B39: MSFT | C39: 2023 | D39: 211.915 | E39: 72.361 | F39: 411.976 | G39: 205.753 | H39: 6.8820295556564215 | I39: 34.14623787839464 | J39: 17.5643726819038 | K39: 49.9429578422044
A40: Microsoft | B40: MSFT | C40: 2024 | D40: 245.122 | E40: 88.136 | F40: 512.163 | G40: 243.686 | H40: 15.669962013071292 | I40: 35.955972944084984 | J40: 17.208583985957596 | K40: 47.57977440775691
...

Sheet Financial_Analysis
A1: company | B1: fiscal_year | C1: revenue_growth_pct (%) | D1: net_profit_margin_pct (%) | E1: roa_pct (%) | F1: liability_to_asset_pct (%)
A2: Adobe | B2: 2021 | D2: 30.547989 | E2: 17.701259 | F2: 45.681142
A3: Adobe | B3: 2022 | C3: 11.536269 | D3: 27.013518 | E3: 17.507823 | F3: 48.275354
A4: Adobe | B4: 2023 | C4: 10.240827 | D4: 27.966407 | E4: 18.22761 | F4: 44.531381
A5: Adobe | B5: 2024 | C5: 10.799114 | D5: 25.854452 | E5: 18.392326 | F5: 53.341052
A6: Adobe | B6: 2025 | C6: 10.527784 | D6: 29.997055 | E6: 24.172769 | F6: 60.594657
A7: Alphabet | B7: 2021 | D7: 29.511677 | E7: 21.16331 | F7: 29.958972
A8: Alphabet | B8: 2022 | C8: 9.7808156 | D8: 21.203807 | E8: 16.418809 | F8: 29.874283
A9: Alphabet | B9: 2023 | C9: 8.6827702 | D9: 24.006649 | E9: 18.339082 | F9: 29.576383
A10: Alphabet | B10: 2024 | C10: 13.866243 | D10: 28.603672 | E10: 22.235795 | F10: 27.800185
A11: Alphabet | B11: 2025 | C11: 15.090081 | D11: 32.809878 | E11: 22.20296 | F11: 30.240508
A12: Amazon | B12: 2021 | D12: 7.1014129 | E12: 7.9334394 | F12: 67.127493
A13: Amazon | B13: 2022 | C13: 9.3995173 | D13: -0.5295895 | E13: -0.58831793 | F13: 68.435079
A14: Amazon | B14: 2023 | C14: 11.829574 | D14: 5.2932836 | E14: 5.7639044 | F14: 61.755523
A15: Amazon | B15: 2024 | C15: 10.990892 | D15: 9.2871172 | E15: 9.481288 | F15: 54.237039
A16: Amazon | B16: 2025 | C16: 12.377755 | D16: 10.833784 | E16: 9.4946225 | F16: 49.750135
A17: Apple | B17: 2021 | D17: 25.881793 | E17: 26.974205 | F17: 82.025743
A18: Apple | B18: 2022 | C18: 7.7937876 | D18: 25.309641 | E18: 28.292441 | F18: 85.635356
A19: Apple | B19: 2023 | C19: -2.8004605 | D19: 25.306234 | E19: 27.509835 | F19: 82.374079
A20: Apple | B20: 2024 | C20: 2.0219941 | D20: 23.971256 | E20: 25.682503 | F20: 84.396405
A21: Apple | B21: 2025 | C21: 6.4255118 | D21: 26.915064 | E21: 31.179626 | F21: 79.475338
A22: Cisco | B22: 2021 | D22: 21.259384 | E22: 10.862898 | F22: 57.665364
A23: Cisco | B23: 2022 | C23: 3.4907062 | D23: 22.910565 | E23: 12.56569 | F23: 57.689198
A24: Cisco | B24: 2023 | C24: 10.553368 | D24: 22.128847 | E24: 12.383655 | F24: 56.453482
A25: Cisco | B25: 2024 | C25: -5.6054598 | D25: 19.181087 | E25: 8.2949531 | F25: 63.462821
A26: Cisco | B26: 2025 | C26: 5.298961 | D26: 17.968722 | E26: 8.3244065 | F26: 61.695464
A27: IBM | B27: 2021 | D27: 10.013949 | E27: 4.3507246 | F27: 85.6092
A28: IBM | B28: 2022 | C28: 5.5448997 | D28: 2.7077482 | E28: 1.2880866 | F28: 82.693743
A29: IBM | B29: 2023 | C29: 2.1972576 | D29: 12.127384 | E29: 5.5471344 | F29: 83.279479
A30: IBM | B30: 2024 | C30: 1.4435823 | D30: 9.5979475 | E30: 4.3907418 | F30: 80.031347
A31: IBM | B31: 2025 | C31: 7.6203528 | D31: 15.6852 | E31: 6.9745852 | F31: 78.44285
A32: Meta | B32: 2021 | D32: 33.384494 | E32: 23.718725 | F32: 24.765795
A33: Meta | B33: 2022 | C33: -1.1193176 | D33: 19.895548 | E33: 12.491453 | F33: 32.313019
A34: Meta | B34: 2023 | C34: 15.687468 | D34: 28.982521 | E34: 17.02704 | F34: 33.295881
A35: Meta | B35: 2024 | C35: 21.941113 | D35: 37.908584 | E35: 22.589783 | F35: 33.840118
A36: Meta | B36: 2025 | C36: 22.167038 | D36: 30.083696 | E36: 16.517632 | F36: 40.647395
A37: Microsoft | B37: 2021 | D37: 36.45174 | E37: 18.356757 | F37: 57.460475
A38: Microsoft | B38: 2022 | C38: 17.956071 | D38: 36.686337 | E38: 19.936959 | F38: 54.352045
A39: Microsoft | B39: 2023 | C39: 6.8820296 | D39: 34.146238 | E39: 17.564373 | F39: 49.942958
A40: Microsoft | B40: 2024 | C40: 15.669962 | D40: 35.955973 | E40: 17.208584 | F40: 47.579774
...

Sheet Analysis
A1: Company | B1: Avg Revenue Growth (%) | C1: Avg Net Profit Margin (%) | D1: Avg ROA (%) | E1: Avg Liability-to-Asset (%)
A2: Adobe | B2: =AVERAGEIF(Financial_Analysis!$A$2:$A$51,A2,Financial_Analysis!$C$2:$C$51) -> 10.775998 | C2: =AVERAGEIF(Financial_Analysis!$A$2:$A$51,A2,Financial_Analysis!$D$2:$D$51) -> 28.275884 | D2: =AVERAGEIF(Financial_Analysis!$A$2:$A$51,A2,Financial_Analysis!$E$2:$E$51) -> 19.200357 | E2: =AVERAGEIF(Financial_Analysis!$A$2:$A$51,A2,Financial_Analysis!$F$2:$F$51) -> 50.484717
A3: Alphabet | B3: =AVERAGEIF(Financial_Analysis!$A$2:$A$51,A3,Financial_Analysis!$C$2:$C$51) -> 11.854978 | C3: =AVERAGEIF(Financial_Analysis!$A$2:$A$51,A3,Financial_Analysis!$D$2:$D$51) -> 27.227137 | D3: =AVERAGEIF(Financial_Analysis!$A$2:$A$51,A3,Financial_Analysis!$E$2:$E$51) -> 20.071991 | E3: =AVERAGEIF(Financial_Analysis!$A$2:$A$51,A3,Financial_Analysis!$F$2:$F$51) -> 29.490066
A4: Amazon | B4: =AVERAGEIF(Financial_Analysis!$A$2:$A$51,A4,Financial_Analysis!$C$2:$C$51) -> 11.149435 | C4: =AVERAGEIF(Financial_Analysis!$A$2:$A$51,A4,Financial_Analysis!$D$2:$D$51) -> 6.3972017 | D4: =AVERAGEIF(Financial_Analysis!$A$2:$A$51,A4,Financial_Analysis!$E$2:$E$51) -> 6.4169873 | E4: =AVERAGEIF(Financial_Analysis!$A$2:$A$51,A4,Financial_Analysis!$F$2:$F$51) -> 60.261054
A5: Apple | B5: =AVERAGEIF(Financial_Analysis!$A$2:$A$51,A5,Financial_Analysis!$C$2:$C$51) -> 3.3602082 | C5: =AVERAGEIF(Financial_Analysis!$A$2:$A$51,A5,Financial_Analysis!$D$2:$D$51) -> 25.476798 | D5: =AVERAGEIF(Financial_Analysis!$A$2:$A$51,A5,Financial_Analysis!$E$2:$E$51) -> 27.927722 | E5: =AVERAGEIF(Financial_Analysis!$A$2:$A$51,A5,Financial_Analysis!$F$2:$F$51) -> 82.781384
A6: Cisco | B6: =AVERAGEIF(Financial_Analysis!$A$2:$A$51,A6,Financial_Analysis!$C$2:$C$51) -> 3.4343939 | C6: =AVERAGEIF(Financial_Analysis!$A$2:$A$51,A6,Financial_Analysis!$D$2:$D$51) -> 20.689721 | D6: =AVERAGEIF(Financial_Analysis!$A$2:$A$51,A6,Financial_Analysis!$E$2:$E$51) -> 10.486321 | E6: =AVERAGEIF(Financial_Analysis!$A$2:$A$51,A6,Financial_Analysis!$F$2:$F$51) -> 59.393266
A7: IBM | B7: =AVERAGEIF(Financial_Analysis!$A$2:$A$51,A7,Financial_Analysis!$C$2:$C$51) -> 4.2015231 | C7: =AVERAGEIF(Financial_Analysis!$A$2:$A$51,A7,Financial_Analysis!$D$2:$D$51) -> 10.026446 | D7: =AVERAGEIF(Financial_Analysis!$A$2:$A$51,A7,Financial_Analysis!$E$2:$E$51) -> 4.5102545 | E7: =AVERAGEIF(Financial_Analysis!$A$2:$A$51,A7,Financial_Analysis!$F$2:$F$51) -> 82.011324
A8: Meta | B8: =AVERAGEIF(Financial_Analysis!$A$2:$A$51,A8,Financial_Analysis!$C$2:$C$51) -> 14.669076 | C8: =AVERAGEIF(Financial_Analysis!$A$2:$A$51,A8,Financial_Analysis!$D$2:$D$51) -> 30.050969 | D8: =AVERAGEIF(Financial_Analysis!$A$2:$A$51,A8,Financial_Analysis!$E$2:$E$51) -> 18.468926 | E8: =AVERAGEIF(Financial_Analysis!$A$2:$A$51,A8,Financial_Analysis!$F$2:$F$51) -> 32.972441
A9: Microsoft | B9: =AVERAGEIF(Financial_Analysis!$A$2:$A$51,A9,Financial_Analysis!$C$2:$C$51) -> 13.860055 | C9: =AVERAGEIF(Financial_Analysis!$A$2:$A$51,A9,Financial_Analysis!$D$2:$D$51) -> 35.87726 | D9: =AVERAGEIF(Financial_Analysis!$A$2:$A$51,A9,Financial_Analysis!$E$2:$E$51) -> 17.903529 | E9: =AVERAGEIF(Financial_Analysis!$A$2:$A$51,A9,Financial_Analysis!$F$2:$F$51) -> 50.769237
A10: NVIDIA | B10: =AVERAGEIF(Financial_Analysis!$A$2:$A$51,A10,Financial_Analysis!$C$2:$C$51) -> 75.421041 | C10: =AVERAGEIF(Financial_Analysis!$A$2:$A$51,A10,Financial_Analysis!$D$2:$D$51) -> 36.620738 | D10: =AVERAGEIF(Financial_Analysis!$A$2:$A$51,A10,Financial_Analysis!$E$2:$E$51) -> 31.660873 | E10: =AVERAGEIF(Financial_Analysis!$A$2:$A$51,A10,Financial_Analysis!$F$2:$F$51) -> 38.192869
A11: Oracle | B11: =AVERAGEIF(Financial_Analysis!$A$2:$A$51,A11,Financial_Analysis!$C$2:$C$51) -> 9.2371929 | C11: =AVERAGEIF(Financial_Analysis!$A$2:$A$51,A11,Financial_Analysis!$D$2:$D$51) -> 21.649747 | D11: =AVERAGEIF(Financial_Analysis!$A$2:$A$51,A11,Financial_Analysis!$E$2:$E$51) -> 7.5545861 | E11: =AVERAGEIF(Financial_Analysis!$A$2:$A$51,A11,Financial_Analysis!$F$2:$F$51) -> 96.515207

Sheet Dashboard
A1: Financial Performance Dashboard
A2: Leading Technology Companies | FY2021–FY2025
A4: Average Revenue Growth (%) | C4: Average Net Profit Margin (%) | E4: Average ROA (%) | G4: Average Liability-to-Asset (%)
A5: =AVERAGE(Analysis!B2:B11) -> 15.79639 | C5: =AVERAGE(Analysis!C2:C11) -> 24.22919 | E5: =AVERAGE(Analysis!D2:D11) -> 16.420155 | G5: =AVERAGE(Analysis!E2:E11) -> 58.287156
A39: Source: SEC Company Facts | FY2021–FY2025 | Ratios calculated using year-end financial data
A40: Note: Revenue Growth averages exclude FY2021 because the dataset begins in FY2021.
